<?xml version="1.0" ?>


<sdf version="1.5">
<model name="stewart_platform">

	<!-- ** Links Definitions ** -->
	<!-- * Base Definitions * -->
	<link name="base_link">
		<!-- Position -->
		<pose>0 0  -0.05  0 0 0</pose>
		<!-- Shape -->
		<collision name="collision">
        <geometry>
          <cylinder>
            <radius> 0.4138840417314975 </radius>
            <length> 0.02 </length>
          </cylinder>
        </geometry>
      </collision>
      <visual name="visual">
        <geometry>
          <cylinder>
            <radius> 0.4138840417314975 </radius>
            <length> 0.02 </length>
          </cylinder>
        </geometry>
      </visual>
	</link>
	<!-- * Base Definitions * -->
	<link name="platform_link">
		<!-- Position -->
		<pose>0 0  0.45  0 0 0</pose>
		<!-- Shape -->
		<collision name="collision">
        <geometry>
          <cylinder>
            <radius> 0.1984313483298443 </radius>
            <length> 0.02 </length>
          </cylinder>
        </geometry>
      </collision>
      <visual name="visual">
        <geometry>
          <cylinder>
            <radius> 0.1984313483298443 </radius>
            <length> 0.02 </length>
          </cylinder>
        </geometry>
      </visual>
	</link>

	
		
		
		<!-- * Motor Definitions * -->
		<link name= "motor_0_link">
			<!-- Position -->
			<pose> 0.29346787517317596 -0.315 0 1.5707963267948966 0 1.5707963267948966</pose>
			<!-- Shape -->
			<collision name="collision">
        <geometry>
          <cylinder>
            <radius> 0.05 </radius>
            <length> 0.05 </length>
          </cylinder>
        </geometry>
      </collision>
      <visual name="visual">
        <geometry>
          <cylinder>
            <radius> 0.05 </radius>
            <length> 0.05 </length>
          </cylinder>
        </geometry>
      </visual>
		</link>
		<!-- * ARM Definitions * -->
		<link name="arm_0_link">
			<!-- Position -->
			<pose>  0.25846787517317593 -0.275 0 1.5707963267948966 0 0.0</pose>
			<!-- Shape -->
			<collision name="collision">
        <geometry>
         <box>
	     <size> 0.02 0.02 0.08 </size>
	 </box>
        </geometry>
      </collision>
      <visual name="visual">
        <geometry>
          <box>
	     <size> 0.02 0.02 0.08 </size>
	 </box>
        </geometry>
      </visual>
		</link>
		<!-- * RotuleDown Definitions * -->
		<link name="rotuleDown_0_link">
			<!-- Position -->
			<pose>  0.26846787517317594 -0.235 0 0 0 0 </pose>
			<!-- Shape -->
			<collision name="collision">
        <geometry>
          <sphere>
	    <radius> 0.02 </radius>
	 </sphere>
        </geometry>
      </collision>
      <visual name="visual">
        <geometry>
          <sphere>
	    <radius> 0.02 </radius>
	 </sphere>
        </geometry>
      </visual>
		</link>
		<!-- * Leg Definitions * -->
		<link name= "leg_0_link">
			<!-- Position -->
			<pose> 0.22166179551233733 -0.13624999999999998 0.190938808016556 0.5198299274421689 0 -2.690311012359247</pose>
			<!-- Shape -->
			<collision name="collision">
        <geometry>
          <cylinder>
            <radius> 0.02 </radius>
            <length> 0.44 </length>
          </cylinder>
        </geometry>
      </collision>
      <visual name="visual">
        <geometry>
          <cylinder>
            <radius> 0.02 </radius>
            <length> 0.44 </length>
          </cylinder>
        </geometry>
      </visual>
		</link>
		<!-- * RotuleUp Definitions * -->
		<link name="rotuleUp_0_link">
			<!-- Position -->
			<pose>  0.17485571585149873 -0.0375 0.381877616033112 0 0 0</pose>
			<!-- Shape -->
			<collision name="collision">
        <geometry>
          <sphere>
	    <radius> 0.02 </radius>
	 </sphere>
        </geometry>
      </collision>
      <visual name="visual">
        <geometry>
          <sphere>
	    <radius> 0.02 </radius>
	 </sphere>
        </geometry>
      </visual>
		</link>

		
		<!-- * Holder Definitions * -->
		<link name="holder_0_link">
			<!-- Position -->
			<pose>  0.17485571585149873 0.0 0.381877616033112 1.5707963267948966 0 0.0</pose>
			<!-- Shape -->
			<collision name="collision">
        <geometry>
         <box>
	     <size> 0.02 0.02 0.075 </size>
	 </box>
        </geometry>
      </collision>
      <visual name="visual">
        <geometry>
          <box>
	     <size> 0.02 0.02 0.075 </size>
	 </box>
        </geometry>
      </visual>
		</link>
		

		<!-- ** Joints Definitions ** -->
		<!-- * Platform-Motor Joint Definitions * -->
		<joint name="mot_fixed_0_joint" type="fixed">
			<parent>base_link</parent>
			<child>motor_0_link</child>
		</joint>
		<!-- * Motor-Arm Joint Definitions * -->
		<joint name="motor_0" type="revolute">
			<pose frame= "arm_0"> 0 0 0.04 0 0 </pose>
			<parent>motor_0_link</parent>
			<child>arm_0_link</child>
			<axis>
				<xyz>1 0 0</xyz>
			</axis>
		</joint>
		<!-- * Arm-RotuleDown Joint Definitions * -->
		<joint name="arm_rotDown_0_joint" type="fixed">
			<parent>arm_0_link</parent>
			<child>rotuleDown_0_link</child>
		</joint>
		<!-- * RotuleDown-Leg Joint Definitions * -->
		<joint name="rotDown_leg_0_joint" type="ball">
			<pose frame= "arm_0_link"> 0 0 -0.22 0 0 </pose>
			<parent>rotuleDown_0_link</parent>
			<child>leg_0_link</child>
		</joint>
		<!-- * Leg-RotuleUp Joint Definitions * -->
		<joint name="arm_rotUp_0_joint" type="fixed">
			<parent>leg_0_link</parent>
			<child>rotuleUp_0_link</child>
		</joint>
		<!-- * RotuleUp-Holder Joint Definitions * -->
		<joint name="rotUp_platform_0_joint" type="ball">
			<pose frame="rotuleUp_0_link"> 0 0 0 0 0 </pose>
			<child>rotuleUp_0_link</child>
			<parent>holder_0_link</parent>
		</joint>
		
		<!-- * RotuleUp-Holder Joint Definitions * -->
		<joint name="holder_platform_0_joint" type="fixed">
			<parent>holder_0_link</parent>
			<child>platform_link</child>
		</joint>
		
	
		
		
		<!-- * Motor Definitions * -->
		<link name= "motor_1_link">
			<!-- Position -->
			<pose> 0.29346787517317596 0.315 0 1.5707963267948966 0 1.5707963267948966</pose>
			<!-- Shape -->
			<collision name="collision">
        <geometry>
          <cylinder>
            <radius> 0.05 </radius>
            <length> 0.05 </length>
          </cylinder>
        </geometry>
      </collision>
      <visual name="visual">
        <geometry>
          <cylinder>
            <radius> 0.05 </radius>
            <length> 0.05 </length>
          </cylinder>
        </geometry>
      </visual>
		</link>
		<!-- * ARM Definitions * -->
		<link name="arm_1_link">
			<!-- Position -->
			<pose>  0.25846787517317593 0.275 0 1.5707963267948966 0 0.0</pose>
			<!-- Shape -->
			<collision name="collision">
        <geometry>
         <box>
	     <size> 0.02 0.02 0.08 </size>
	 </box>
        </geometry>
      </collision>
      <visual name="visual">
        <geometry>
          <box>
	     <size> 0.02 0.02 0.08 </size>
	 </box>
        </geometry>
      </visual>
		</link>
		<!-- * RotuleDown Definitions * -->
		<link name="rotuleDown_1_link">
			<!-- Position -->
			<pose>  0.26846787517317594 0.235 0 0 0 0 </pose>
			<!-- Shape -->
			<collision name="collision">
        <geometry>
          <sphere>
	    <radius> 0.02 </radius>
	 </sphere>
        </geometry>
      </collision>
      <visual name="visual">
        <geometry>
          <sphere>
	    <radius> 0.02 </radius>
	 </sphere>
        </geometry>
      </visual>
		</link>
		<!-- * Leg Definitions * -->
		<link name= "leg_1_link">
			<!-- Position -->
			<pose> 0.22166179551233733 0.13624999999999998 0.190938808016556 0.5198299274421689 0 -0.45128164123054637</pose>
			<!-- Shape -->
			<collision name="collision">
        <geometry>
          <cylinder>
            <radius> 0.02 </radius>
            <length> 0.44 </length>
          </cylinder>
        </geometry>
      </collision>
      <visual name="visual">
        <geometry>
          <cylinder>
            <radius> 0.02 </radius>
            <length> 0.44 </length>
          </cylinder>
        </geometry>
      </visual>
		</link>
		<!-- * RotuleUp Definitions * -->
		<link name="rotuleUp_1_link">
			<!-- Position -->
			<pose>  0.17485571585149873 0.0375 0.381877616033112 0 0 0</pose>
			<!-- Shape -->
			<collision name="collision">
        <geometry>
          <sphere>
	    <radius> 0.02 </radius>
	 </sphere>
        </geometry>
      </collision>
      <visual name="visual">
        <geometry>
          <sphere>
	    <radius> 0.02 </radius>
	 </sphere>
        </geometry>
      </visual>
		</link>

		

		<!-- ** Joints Definitions ** -->
		<!-- * Platform-Motor Joint Definitions * -->
		<joint name="mot_fixed_1_joint" type="fixed">
			<parent>base_link</parent>
			<child>motor_1_link</child>
		</joint>
		<!-- * Motor-Arm Joint Definitions * -->
		<joint name="motor_1" type="revolute">
			<pose frame= "arm_1"> 0 0 -0.04 0 0 </pose>
			<parent>motor_1_link</parent>
			<child>arm_1_link</child>
			<axis>
				<xyz>1 0 0</xyz>
			</axis>
		</joint>
		<!-- * Arm-RotuleDown Joint Definitions * -->
		<joint name="arm_rotDown_1_joint" type="fixed">
			<parent>arm_1_link</parent>
			<child>rotuleDown_1_link</child>
		</joint>
		<!-- * RotuleDown-Leg Joint Definitions * -->
		<joint name="rotDown_leg_1_joint" type="ball">
			<pose frame= "arm_1_link"> 0 0 -0.22 0 0 </pose>
			<parent>rotuleDown_1_link</parent>
			<child>leg_1_link</child>
		</joint>
		<!-- * Leg-RotuleUp Joint Definitions * -->
		<joint name="arm_rotUp_1_joint" type="fixed">
			<parent>leg_1_link</parent>
			<child>rotuleUp_1_link</child>
		</joint>
		<!-- * RotuleUp-Holder Joint Definitions * -->
		<joint name="rotUp_platform_1_joint" type="ball">
			<pose frame="rotuleUp_1_link"> 0 0 0 0 0 </pose>
			<child>rotuleUp_1_link</child>
			<parent>holder_0_link</parent>
		</joint>
		
	
		
		
		<!-- * Motor Definitions * -->
		<link name= "motor_2_link">
			<!-- Position -->
			<pose> 0.12606406460551028 0.41165063509461086 0 1.5707963267948966 0 3.665191429188092</pose>
			<!-- Shape -->
			<collision name="collision">
        <geometry>
          <cylinder>
            <radius> 0.05 </radius>
            <length> 0.05 </length>
          </cylinder>
        </geometry>
      </collision>
      <visual name="visual">
        <geometry>
          <cylinder>
            <radius> 0.05 </radius>
            <length> 0.05 </length>
          </cylinder>
        </geometry>
      </visual>
		</link>
		<!-- * ARM Definitions * -->
		<link name="arm_2_link">
			<!-- Position -->
			<pose>  0.10892304845413273 0.36133974596215557 0 1.5707963267948966 0 2.0943951023931953</pose>
			<!-- Shape -->
			<collision name="collision">
        <geometry>
         <box>
	     <size> 0.02 0.02 0.08 </size>
	 </box>
        </geometry>
      </collision>
      <visual name="visual">
        <geometry>
          <box>
	     <size> 0.02 0.02 0.08 </size>
	 </box>
        </geometry>
      </visual>
		</link>
		<!-- * RotuleDown Definitions * -->
		<link name="rotuleDown_2_link">
			<!-- Position -->
			<pose>  0.06928203230275518 0.3499999999999999 0 0 0 0 </pose>
			<!-- Shape -->
			<collision name="collision">
        <geometry>
          <sphere>
	    <radius> 0.02 </radius>
	 </sphere>
        </geometry>
      </collision>
      <visual name="visual">
        <geometry>
          <sphere>
	    <radius> 0.02 </radius>
	 </sphere>
        </geometry>
      </visual>
		</link>
		<!-- * Leg Definitions * -->
		<link name= "leg_2_link">
			<!-- Position -->
			<pose> 0.007165063509461146 0.2600897459621556 0.190938808016556 0.5198299274421689 0 -0.5959159099660516</pose>
			<!-- Shape -->
			<collision name="collision">
        <geometry>
          <cylinder>
            <radius> 0.02 </radius>
            <length> 0.44 </length>
          </cylinder>
        </geometry>
      </collision>
      <visual name="visual">
        <geometry>
          <cylinder>
            <radius> 0.02 </radius>
            <length> 0.44 </length>
          </cylinder>
        </geometry>
      </visual>
		</link>
		<!-- * RotuleUp Definitions * -->
		<link name="rotuleUp_2_link">
			<!-- Position -->
			<pose>  -0.05495190528383288 0.17017949192431125 0.381877616033112 0 0 0</pose>
			<!-- Shape -->
			<collision name="collision">
        <geometry>
          <sphere>
	    <radius> 0.02 </radius>
	 </sphere>
        </geometry>
      </collision>
      <visual name="visual">
        <geometry>
          <sphere>
	    <radius> 0.02 </radius>
	 </sphere>
        </geometry>
      </visual>
		</link>

		
		<!-- * Holder Definitions * -->
		<link name="holder_1_link">
			<!-- Position -->
			<pose>  -0.08742785792574934 0.15142949192431127 0.381877616033112 1.5707963267948966 0 2.0943951023931953</pose>
			<!-- Shape -->
			<collision name="collision">
        <geometry>
         <box>
	     <size> 0.02 0.02 0.075 </size>
	 </box>
        </geometry>
      </collision>
      <visual name="visual">
        <geometry>
          <box>
	     <size> 0.02 0.02 0.075 </size>
	 </box>
        </geometry>
      </visual>
		</link>
		

		<!-- ** Joints Definitions ** -->
		<!-- * Platform-Motor Joint Definitions * -->
		<joint name="mot_fixed_2_joint" type="fixed">
			<parent>base_link</parent>
			<child>motor_2_link</child>
		</joint>
		<!-- * Motor-Arm Joint Definitions * -->
		<joint name="motor_2" type="revolute">
			<pose frame= "arm_2"> 0 0 0.04 0 0 </pose>
			<parent>motor_2_link</parent>
			<child>arm_2_link</child>
			<axis>
				<xyz>1 0 0</xyz>
			</axis>
		</joint>
		<!-- * Arm-RotuleDown Joint Definitions * -->
		<joint name="arm_rotDown_2_joint" type="fixed">
			<parent>arm_2_link</parent>
			<child>rotuleDown_2_link</child>
		</joint>
		<!-- * RotuleDown-Leg Joint Definitions * -->
		<joint name="rotDown_leg_2_joint" type="ball">
			<pose frame= "arm_2_link"> 0 0 -0.22 0 0 </pose>
			<parent>rotuleDown_2_link</parent>
			<child>leg_2_link</child>
		</joint>
		<!-- * Leg-RotuleUp Joint Definitions * -->
		<joint name="arm_rotUp_2_joint" type="fixed">
			<parent>leg_2_link</parent>
			<child>rotuleUp_2_link</child>
		</joint>
		<!-- * RotuleUp-Holder Joint Definitions * -->
		<joint name="rotUp_platform_2_joint" type="ball">
			<pose frame="rotuleUp_2_link"> 0 0 0 0 0 </pose>
			<child>rotuleUp_2_link</child>
			<parent>holder_1_link</parent>
		</joint>
		
		<!-- * RotuleUp-Holder Joint Definitions * -->
		<joint name="holder_platform_1_joint" type="fixed">
			<parent>holder_1_link</parent>
			<child>platform_link</child>
		</joint>
		
	
		
		
		<!-- * Motor Definitions * -->
		<link name= "motor_3_link">
			<!-- Position -->
			<pose> -0.41953193977868614 0.09665063509461105 0 1.5707963267948966 0 3.665191429188092</pose>
			<!-- Shape -->
			<collision name="collision">
        <geometry>
          <cylinder>
            <radius> 0.05 </radius>
            <length> 0.05 </length>
          </cylinder>
        </geometry>
      </collision>
      <visual name="visual">
        <geometry>
          <cylinder>
            <radius> 0.05 </radius>
            <length> 0.05 </length>
          </cylinder>
        </geometry>
      </visual>
		</link>
		<!-- * ARM Definitions * -->
		<link name="arm_3_link">
			<!-- Position -->
			<pose>  -0.3673909236273086 0.08633974596215568 0 1.5707963267948966 0 2.0943951023931953</pose>
			<!-- Shape -->
			<collision name="collision">
        <geometry>
         <box>
	     <size> 0.02 0.02 0.08 </size>
	 </box>
        </geometry>
      </collision>
      <visual name="visual">
        <geometry>
          <box>
	     <size> 0.02 0.02 0.08 </size>
	 </box>
        </geometry>
      </visual>
		</link>
		<!-- * RotuleDown Definitions * -->
		<link name="rotuleDown_3_link">
			<!-- Position -->
			<pose>  -0.33774990747593103 0.11500000000000006 0 0 0 0 </pose>
			<!-- Shape -->
			<collision name="collision">
        <geometry>
          <sphere>
	    <radius> 0.02 </radius>
	 </sphere>
        </geometry>
      </collision>
      <visual name="visual">
        <geometry>
          <sphere>
	    <radius> 0.02 </radius>
	 </sphere>
        </geometry>
      </visual>
		</link>
		<!-- * Leg Definitions * -->
		<link name= "leg_3_link">
			<!-- Position -->
			<pose> -0.2288268590217984 0.12383974596215566 0.190938808016556 0.5198299274421689 0 1.6431134611626488</pose>
			<!-- Shape -->
			<collision name="collision">
        <geometry>
          <cylinder>
            <radius> 0.02 </radius>
            <length> 0.44 </length>
          </cylinder>
        </geometry>
      </collision>
      <visual name="visual">
        <geometry>
          <cylinder>
            <radius> 0.02 </radius>
            <length> 0.44 </length>
          </cylinder>
        </geometry>
      </visual>
		</link>
		<!-- * RotuleUp Definitions * -->
		<link name="rotuleUp_3_link">
			<!-- Position -->
			<pose>  -0.11990381056766576 0.13267949192431125 0.381877616033112 0 0 0</pose>
			<!-- Shape -->
			<collision name="collision">
        <geometry>
          <sphere>
	    <radius> 0.02 </radius>
	 </sphere>
        </geometry>
      </collision>
      <visual name="visual">
        <geometry>
          <sphere>
	    <radius> 0.02 </radius>
	 </sphere>
        </geometry>
      </visual>
		</link>

		

		<!-- ** Joints Definitions ** -->
		<!-- * Platform-Motor Joint Definitions * -->
		<joint name="mot_fixed_3_joint" type="fixed">
			<parent>base_link</parent>
			<child>motor_3_link</child>
		</joint>
		<!-- * Motor-Arm Joint Definitions * -->
		<joint name="motor_3" type="revolute">
			<pose frame= "arm_3"> 0 0 -0.04 0 0 </pose>
			<parent>motor_3_link</parent>
			<child>arm_3_link</child>
			<axis>
				<xyz>1 0 0</xyz>
			</axis>
		</joint>
		<!-- * Arm-RotuleDown Joint Definitions * -->
		<joint name="arm_rotDown_3_joint" type="fixed">
			<parent>arm_3_link</parent>
			<child>rotuleDown_3_link</child>
		</joint>
		<!-- * RotuleDown-Leg Joint Definitions * -->
		<joint name="rotDown_leg_3_joint" type="ball">
			<pose frame= "arm_3_link"> 0 0 -0.22 0 0 </pose>
			<parent>rotuleDown_3_link</parent>
			<child>leg_3_link</child>
		</joint>
		<!-- * Leg-RotuleUp Joint Definitions * -->
		<joint name="arm_rotUp_3_joint" type="fixed">
			<parent>leg_3_link</parent>
			<child>rotuleUp_3_link</child>
		</joint>
		<!-- * RotuleUp-Holder Joint Definitions * -->
		<joint name="rotUp_platform_3_joint" type="ball">
			<pose frame="rotuleUp_3_link"> 0 0 0 0 0 </pose>
			<child>rotuleUp_3_link</child>
			<parent>holder_1_link</parent>
		</joint>
		
	
		
		
		<!-- * Motor Definitions * -->
		<link name= "motor_4_link">
			<!-- Position -->
			<pose> -0.4195319397786862 -0.09665063509461076 0 1.5707963267948966 0 5.759586531581287</pose>
			<!-- Shape -->
			<collision name="collision">
        <geometry>
          <cylinder>
            <radius> 0.05 </radius>
            <length> 0.05 </length>
          </cylinder>
        </geometry>
      </collision>
      <visual name="visual">
        <geometry>
          <cylinder>
            <radius> 0.05 </radius>
            <length> 0.05 </length>
          </cylinder>
        </geometry>
      </visual>
		</link>
		<!-- * ARM Definitions * -->
		<link name="arm_4_link">
			<!-- Position -->
			<pose>  -0.36739092362730863 -0.08633974596215543 0 1.5707963267948966 0 4.1887902047863905</pose>
			<!-- Shape -->
			<collision name="collision">
        <geometry>
         <box>
	     <size> 0.02 0.02 0.08 </size>
	 </box>
        </geometry>
      </collision>
      <visual name="visual">
        <geometry>
          <box>
	     <size> 0.02 0.02 0.08 </size>
	 </box>
        </geometry>
      </visual>
		</link>
		<!-- * RotuleDown Definitions * -->
		<link name="rotuleDown_4_link">
			<!-- Position -->
			<pose>  -0.3377499074759311 -0.11499999999999984 0 0 0 0 </pose>
			<!-- Shape -->
			<collision name="collision">
        <geometry>
          <sphere>
	    <radius> 0.02 </radius>
	 </sphere>
        </geometry>
      </collision>
      <visual name="visual">
        <geometry>
          <sphere>
	    <radius> 0.02 </radius>
	 </sphere>
        </geometry>
      </visual>
		</link>
		<!-- * Leg Definitions * -->
		<link name= "leg_4_link">
			<!-- Position -->
			<pose> -0.22882685902179847 -0.1238397459621555 0.190938808016556 0.5198299274421689 0 1.498479192427144</pose>
			<!-- Shape -->
			<collision name="collision">
        <geometry>
          <cylinder>
            <radius> 0.02 </radius>
            <length> 0.44 </length>
          </cylinder>
        </geometry>
      </collision>
      <visual name="visual">
        <geometry>
          <cylinder>
            <radius> 0.02 </radius>
            <length> 0.44 </length>
          </cylinder>
        </geometry>
      </visual>
		</link>
		<!-- * RotuleUp Definitions * -->
		<link name="rotuleUp_4_link">
			<!-- Position -->
			<pose>  -0.11990381056766586 -0.13267949192431117 0.381877616033112 0 0 0</pose>
			<!-- Shape -->
			<collision name="collision">
        <geometry>
          <sphere>
	    <radius> 0.02 </radius>
	 </sphere>
        </geometry>
      </collision>
      <visual name="visual">
        <geometry>
          <sphere>
	    <radius> 0.02 </radius>
	 </sphere>
        </geometry>
      </visual>
		</link>

		
		<!-- * Holder Definitions * -->
		<link name="holder_2_link">
			<!-- Position -->
			<pose>  -0.08742785792574942 -0.15142949192431118 0.381877616033112 1.5707963267948966 0 4.1887902047863905</pose>
			<!-- Shape -->
			<collision name="collision">
        <geometry>
         <box>
	     <size> 0.02 0.02 0.075 </size>
	 </box>
        </geometry>
      </collision>
      <visual name="visual">
        <geometry>
          <box>
	     <size> 0.02 0.02 0.075 </size>
	 </box>
        </geometry>
      </visual>
		</link>
		

		<!-- ** Joints Definitions ** -->
		<!-- * Platform-Motor Joint Definitions * -->
		<joint name="mot_fixed_4_joint" type="fixed">
			<parent>base_link</parent>
			<child>motor_4_link</child>
		</joint>
		<!-- * Motor-Arm Joint Definitions * -->
		<joint name="motor_4" type="revolute">
			<pose frame= "arm_4"> 0 0 0.04 0 0 </pose>
			<parent>motor_4_link</parent>
			<child>arm_4_link</child>
			<axis>
				<xyz>1 0 0</xyz>
			</axis>
		</joint>
		<!-- * Arm-RotuleDown Joint Definitions * -->
		<joint name="arm_rotDown_4_joint" type="fixed">
			<parent>arm_4_link</parent>
			<child>rotuleDown_4_link</child>
		</joint>
		<!-- * RotuleDown-Leg Joint Definitions * -->
		<joint name="rotDown_leg_4_joint" type="ball">
			<pose frame= "arm_4_link"> 0 0 -0.22 0 0 </pose>
			<parent>rotuleDown_4_link</parent>
			<child>leg_4_link</child>
		</joint>
		<!-- * Leg-RotuleUp Joint Definitions * -->
		<joint name="arm_rotUp_4_joint" type="fixed">
			<parent>leg_4_link</parent>
			<child>rotuleUp_4_link</child>
		</joint>
		<!-- * RotuleUp-Holder Joint Definitions * -->
		<joint name="rotUp_platform_4_joint" type="ball">
			<pose frame="rotuleUp_4_link"> 0 0 0 0 0 </pose>
			<child>rotuleUp_4_link</child>
			<parent>holder_2_link</parent>
		</joint>
		
		<!-- * RotuleUp-Holder Joint Definitions * -->
		<joint name="holder_platform_2_joint" type="fixed">
			<parent>holder_2_link</parent>
			<child>platform_link</child>
		</joint>
		
	
		
		
		<!-- * Motor Definitions * -->
		<link name= "motor_5_link">
			<!-- Position -->
			<pose> 0.12606406460551017 -0.4116506350946109 0 1.5707963267948966 0 5.759586531581287</pose>
			<!-- Shape -->
			<collision name="collision">
        <geometry>
          <cylinder>
            <radius> 0.05 </radius>
            <length> 0.05 </length>
          </cylinder>
        </geometry>
      </collision>
      <visual name="visual">
        <geometry>
          <cylinder>
            <radius> 0.05 </radius>
            <length> 0.05 </length>
          </cylinder>
        </geometry>
      </visual>
		</link>
		<!-- * ARM Definitions * -->
		<link name="arm_5_link">
			<!-- Position -->
			<pose>  0.10892304845413264 -0.36133974596215557 0 1.5707963267948966 0 4.1887902047863905</pose>
			<!-- Shape -->
			<collision name="collision">
        <geometry>
         <box>
	     <size> 0.02 0.02 0.08 </size>
	 </box>
        </geometry>
      </collision>
      <visual name="visual">
        <geometry>
          <box>
	     <size> 0.02 0.02 0.08 </size>
	 </box>
        </geometry>
      </visual>
		</link>
		<!-- * RotuleDown Definitions * -->
		<link name="rotuleDown_5_link">
			<!-- Position -->
			<pose>  0.0692820323027551 -0.3499999999999999 0 0 0 0 </pose>
			<!-- Shape -->
			<collision name="collision">
        <geometry>
          <sphere>
	    <radius> 0.02 </radius>
	 </sphere>
        </geometry>
      </collision>
      <visual name="visual">
        <geometry>
          <sphere>
	    <radius> 0.02 </radius>
	 </sphere>
        </geometry>
      </visual>
		</link>
		<!-- * Leg Definitions * -->
		<link name= "leg_5_link">
			<!-- Position -->
			<pose> 0.007165063509461098 -0.26008974596215556 0.19093880801655602 0.5198299274421687 0 3.7375085635558443</pose>
			<!-- Shape -->
			<collision name="collision">
        <geometry>
          <cylinder>
            <radius> 0.02 </radius>
            <length> 0.44 </length>
          </cylinder>
        </geometry>
      </collision>
      <visual name="visual">
        <geometry>
          <cylinder>
            <radius> 0.02 </radius>
            <length> 0.44 </length>
          </cylinder>
        </geometry>
      </visual>
		</link>
		<!-- * RotuleUp Definitions * -->
		<link name="rotuleUp_5_link">
			<!-- Position -->
			<pose>  -0.05495190528383291 -0.17017949192431123 0.38187761603311204 0 0 0</pose>
			<!-- Shape -->
			<collision name="collision">
        <geometry>
          <sphere>
	    <radius> 0.02 </radius>
	 </sphere>
        </geometry>
      </collision>
      <visual name="visual">
        <geometry>
          <sphere>
	    <radius> 0.02 </radius>
	 </sphere>
        </geometry>
      </visual>
		</link>

		

		<!-- ** Joints Definitions ** -->
		<!-- * Platform-Motor Joint Definitions * -->
		<joint name="mot_fixed_5_joint" type="fixed">
			<parent>base_link</parent>
			<child>motor_5_link</child>
		</joint>
		<!-- * Motor-Arm Joint Definitions * -->
		<joint name="motor_5" type="revolute">
			<pose frame= "arm_5"> 0 0 -0.04 0 0 </pose>
			<parent>motor_5_link</parent>
			<child>arm_5_link</child>
			<axis>
				<xyz>1 0 0</xyz>
			</axis>
		</joint>
		<!-- * Arm-RotuleDown Joint Definitions * -->
		<joint name="arm_rotDown_5_joint" type="fixed">
			<parent>arm_5_link</parent>
			<child>rotuleDown_5_link</child>
		</joint>
		<!-- * RotuleDown-Leg Joint Definitions * -->
		<joint name="rotDown_leg_5_joint" type="ball">
			<pose frame= "arm_5_link"> 0 0 -0.22 0 0 </pose>
			<parent>rotuleDown_5_link</parent>
			<child>leg_5_link</child>
		</joint>
		<!-- * Leg-RotuleUp Joint Definitions * -->
		<joint name="arm_rotUp_5_joint" type="fixed">
			<parent>leg_5_link</parent>
			<child>rotuleUp_5_link</child>
		</joint>
		<!-- * RotuleUp-Holder Joint Definitions * -->
		<joint name="rotUp_platform_5_joint" type="ball">
			<pose frame="rotuleUp_5_link"> 0 0 0 0 0 </pose>
			<child>rotuleUp_5_link</child>
			<parent>holder_2_link</parent>
		</joint>
		
	
</model>
</sdf>
